<?xml version="1.0" encoding="utf-8"?>
<!-- =================================================================================== -->
<!-- |    This document was autogenerated by xacro from sekil10.xacro                  | -->
<!-- |    EDITING THIS FILE BY HAND IS NOT RECOMMENDED                                 | -->
<!-- =================================================================================== -->
<robot name="anka_xacro" xmlns:xacro="http://www.ros.org/wiki/xacro">
  <xacro:include filename="$(find models)/urdf/lidar.gazebo"/>
  <xacro:include filename="$(find models)/urdf/stereo_camera.gazebo"/>
  <link name="base_link">
    <visual>
      <origin rpy="0 0 0" xyz="0 0 0.02"/>
      <geometry>
        <cylinder length="0.01" radius="0.01"/>
      </geometry>
    </visual>
    <collision>
      <geometry>
        <cylinder length="0.1" radius="0.1"/>
      </geometry>
      <origin rpy="0 0 0" xyz="0 0 0.2"/>
    </collision>
    
....
    
......
    <inertial>
      <mass value="0"/>
      <inertia ixx="1.0" ixy="0.0" ixz="0.0" iyy="1.0" iyz="0.0" izz="1.0"/>
    </inertial>
    
..
    
..
  </link>
  

..
  <link name="body">
    <visual>
      <origin rpy="0 0 0" xyz="0 0 0"/>
      <geometry>
        <mesh filename="file:///home/tapdk/model1/src/models/urdf/untitled.dae" scale="0.001 0.001 0.001"/>
      </geometry>
    </visual>
    <collision>
      <geometry>
        <mesh filename="file:///home/tapdk/model1/src/models/urdf/untitled.dae" scale="0.001 0.001 0.001"/>
      </geometry>
      <origin rpy="0 0 0" xyz="0 0 0"/>
    </collision>
    
....
    
......
    <inertial>
      <mass value="10"/>
      <inertia ixx="1.0" ixy="0.0" ixz="0.0" iyy="1.0" iyz="0.0" izz="1.0"/>
    </inertial>
    
..
    
..
  </link>
  

..
  <joint name="base_to_body" type="fixed">
    
...
    <parent link="base_link"/>
    
...
    <child link="body"/>
    
....
    <axis xyz="0 0 0"/>
    
...
    <origin rpy="1.57075 0 0" xyz="0 0 0.615"/>
    
..
  </joint>
  
..

..
  <link name="right_front_wheel">
    
....
    <visual>
      
..........
      <origin rpy="0 0 0" xyz="0 0 0"/>
      <geometry>
        <mesh filename="file:///home/tapdk/model1/src/models/urdf/origin_siyah.dae" scale="0.001 0.001 0.001"/>
      </geometry>
    </visual>
    <collision>
      <geometry>
        <mesh filename="file:///home/tapdk/model1/src/models/urdf/origin_siyah.dae" scale="0.001 0.001 0.001"/>
      </geometry>
      <origin rpy="0 0 0" xyz="0 0 0"/>
    </collision>
    
....
    
......
    <inertial>
      <mass value="2"/>
      <inertia ixx="1.0" ixy="0.0" ixz="0.0" iyy="1.0" iyz="0.0" izz="1.0"/>
    </inertial>
    
..
    
..
  </link>
  

..
  <joint name="base_to_rigth_front_wheel" type="continuous">
    
...
    <parent link="base_link"/>
    
...
    <child link="right_front_wheel"/>
    
....
    <axis xyz="1 0 0"/>
    
...
    <origin xyz="0.65 0.965 0.28"/>
    <limit effort="100" velocity="100"/>
    
..
  </joint>
  <gazebo reference="right_front_wheel">
    <mu1 value="200.0"/>
    <mu2 value="100.0"/>
    <kp value="10000000.0"/>
    <kd value="1.0"/>
  </gazebo>
  <transmission name="right_front_wheel_trans">
    <type>transmission_interface/SimpleTransmission</type>
    <actuator name="$right_front_wheel_motor">
      <hardwareInterface>VelocityJointInterface</hardwareInterface>
      <mechanicalReduction>1</mechanicalReduction>
    </actuator>
    <joint name="base_to_rigth_front_wheel">
      <hardwareInterface>hardware_interface/VelocityJointInterface</hardwareInterface>
    </joint>
  </transmission>
  

....
  <link name="left_front_wheel">
    
....
    <visual>
      
..........
      <origin rpy="0 0 0" xyz="0 0 0"/>
      <geometry>
        <mesh filename="file:///home/tapdk/model1/src/models/urdf/origin_siyah.dae" scale="0.001 0.001 0.001"/>
      </geometry>
    </visual>
    <collision>
      <geometry>
        <mesh filename="file:///home/tapdk/model1/src/models/urdf/origin_siyah.dae" scale="0.001 0.001 0.001"/>
      </geometry>
      <origin rpy="0 0 0" xyz="0 0 0"/>
    </collision>
    
....
    
......
    <inertial>
      <mass value="10"/>
      <inertia ixx="1.0" ixy="0.0" ixz="0.0" iyy="1.0" iyz="0.0" izz="1.0"/>
    </inertial>
    
..
    
..
  </link>
  

..
  <joint name="base_to_left_front_wheel" type="continuous">
    
...
    <parent link="base_link"/>
    
...
    <child link="left_front_wheel"/>
    
...
    <axis xyz="1 0 0"/>
    
...
    <origin xyz="-0.65 0.965 0.28"/>
    <limit effort="100" velocity="100"/>
    
..
  </joint>
  <gazebo reference="left_front_wheel">
    <mu1 value="200.0"/>
    <mu2 value="100.0"/>
    <kp value="10000000.0"/>
    <kd value="1.0"/>
  </gazebo>
  <transmission name="left_front_wheel_trans">
    <type>transmission_interface/SimpleTransmission</type>
    <actuator name="$left_front_wheel_motor">
      <hardwareInterface>VelocityJointInterface</hardwareInterface>
      <mechanicalReduction>1</mechanicalReduction>
    </actuator>
    <joint name="base_to_left_front_wheel">
      <hardwareInterface>hardware_interface/VelocityJointInterface</hardwareInterface>
    </joint>
  </transmission>
  <link name="left_rear_wheel">
    <visual>
      <origin rpy="0 0 0" xyz="0 0 0"/>
      <geometry>
        <mesh filename="file:///home/tapdk/model1/src/models/urdf/origin_siyah.dae" scale="0.001 0.001 0.001"/>
      </geometry>
    </visual>
    <collision>
      <geometry>
        <mesh filename="file:///home/tapdk/model1/src/models/urdf/origin_siyah.dae" scale="0.001 0.001 0.001"/>
      </geometry>
      <origin rpy="0 0 0" xyz="0 0 0"/>
    </collision>
    
....
    
......
    <inertial>
      <mass value="2"/>
      <inertia ixx="1.0" ixy="0.0" ixz="0.0" iyy="1.0" iyz="0.0" izz="1.0"/>
    </inertial>
    
..
  </link>
  
..

  <joint name="base_to_left_rear_wheel" type="continuous">
    <parent link="base_link"/>
    <child link="left_rear_wheel"/>
    <axis xyz="1 0 0"/>
    <origin xyz="-0.65 -0.742 0.28"/>
    <limit effort="100" velocity="100"/>
  </joint>
  <gazebo reference="left_rear_wheel">
    <mu1 value="200.0"/>
    <mu2 value="100.0"/>
    <kp value="10000000.0"/>
    <kd value="1.0"/>
  </gazebo>
  <transmission name="left_rear_wheel_trans">
    <type>transmission_interface/SimpleTransmission</type>
    <actuator name="$left_rear_wheel_motor">
      <mechanicalReduction>1</mechanicalReduction>
      <hardwareInterface>VelocityJointInterface</hardwareInterface>
    </actuator>
    <joint name="base_to_left_rear_wheel">
      <hardwareInterface>hardware_interface/VelocityJointInterface</hardwareInterface>
    </joint>
  </transmission>
  <link name="right_rear_wheel">
    <visual>
      <origin rpy="0 0 0" xyz="0 0 0"/>
      <geometry>
        <mesh filename="file:///home/tapdk/model1/src/models/urdf/origin_siyah.dae" scale="0.001 0.001 0.001"/>
      </geometry>
    </visual>
    <collision>
      <geometry>
        <mesh filename="file:///home/tapdk/model1/src/models/urdf/origin_siyah.dae" scale="0.001 0.001 0.001"/>
      </geometry>
      <origin rpy="0 0 0" xyz="0 0 0"/>
    </collision>
    
....
    
......
    <inertial>
      <mass value="2"/>
      <inertia ixx="1.0" ixy="0.0" ixz="0.0" iyy="1.0" iyz="0.0" izz="1.0"/>
    </inertial>
    
..
  </link>
  
..

  <joint name="base_to_right_rear_wheel" type="continuous">
    <parent link="base_link"/>
    <child link="right_rear_wheel"/>
    <axis xyz="1 0 0"/>
    <origin xyz="0.65 -0.742 0.28"/>
    <limit effort="100" velocity="100"/>
  </joint>
  <gazebo reference="right_rear_wheel">
    <mu1 value="200.0"/>
    <mu2 value="100.0"/>
    <kp value="10000000.0"/>
    <kd value="1.0"/>
  </gazebo>
  <transmission name="right_rear_wheel_trans">
    <type>transmission_interface/SimpleTransmission</type>
    <actuator name="$right_rear_wheel_motor">
      <hardwareInterface>VelocityJointInterface</hardwareInterface>
      <mechanicalReduction>1</mechanicalReduction>
    </actuator>
    <joint name="base_to_right_rear_wheel">
      <hardwareInterface>hardware_interface/VelocityJointInterface</hardwareInterface>
    </joint>
  </transmission>

  <link name="box">
    <visual>
      <geometry>
        <box size="0.2 0.2 0.2"/>
      </geometry>
    </visual>
    <collision>
      <geometry>
        <box size="0.2 0.2 0.2"/>
      </geometry>
    </collision>
    
....
    
......
    <inertial>
      <mass value="2"/>
      <inertia ixx="1.0" ixy="0.0" ixz="0.0" iyy="1.0" iyz="0.0" izz="1.0"/>
    </inertial>
    
..
  </link>

  <joint name="base_to_box" type="fixed">
    <parent link="base_link"/>
    <child link="box"/>
    <origin xyz="0 1.2 0.60"/>
  </joint>
  
    <link name="hokuyo">
    <collision>
      <origin xyz="0 0 0" rpy="0 0 0"/>
      <geometry>
        <box size="0.1 0.1 0.1"/>
      </geometry>
    </collision>

    <visual>
      <origin xyz="0 0 0" rpy="0 0 0"/>
      <geometry>
        <mesh filename="package://models/urdf/hokuyo.dae"/>
      </geometry>
    </visual>
    <inertial>
      <mass value="1e-5" />
      <origin xyz="0 0 0" rpy="0 0 0"/>
      <inertia ixx="1e-6" ixy="0" ixz="0" iyy="1e-6" iyz="0" izz="1e-6" />
    </inertial>
  </link>
  
 
  <joint name="base_to_hokuyo" type="fixed">
    <parent link="base_link"/>
    <child link="hokuyo"/>
    <origin rpy="-0 0.0436 1.57075" xyz="0 1.2 0.73"/>
  </joint>

   <link name="camera_frame">
    <visual>
      <geometry>
        <box size="0.1 0.1 0.1"/>
      </geometry>
    </visual>
    <collision>
      <geometry>
        <box size="0.1 0.1 0.1"/>
      </geometry>
    </collision>
    <inertial>
      <mass value="1e-5" />
      <origin xyz="0 0 0" rpy="0 0 0"/>
      <inertia ixx="1e-6" ixy="0" ixz="0" iyy="1e-6" iyz="0" izz="1e-6" />
    </inertial>
  </link>

   <joint name="base_to_camera_frame" type="fixed">
    <parent link="base_link"/>
    <child link="camera_frame"/>
    <origin rpy="0 0 1.57075" xyz="0 1.35 0.65"/>
  </joint>

  <gazebo>
    <plugin filename="libgazebo_ros_control.so" name="gazebo_ros_control">
      <robotNamespace>/</robotNamespace>
      <legacyModeNS>true</legacyModeNS>
    </plugin>
  </gazebo>

</robot>

